# 6.3 使用 promise

> promise对象是对我们现在尚未得到但将来会得到值的占位符



```javascript
const ninjaPromise = new Promise((resolve,reject) => {  //传入两个函数参数
    resolve("Hattori");
});

ninjaPromise.then(ninja => {
    assert(ninja === "Hattori","We were promised Hattori!");
},err => {
    fail("There shouldn't be an error");
})
```



用新的内置构造函数Promise 创建一个 promise 需要传入一个函数,这个函数被称为 **执行函数** ，它包含两个参数 resolve 和 reject。当把这两个内置函数：resolve 和 reject 作为参数传入 Promise 构造函数后，<u>执行函数会立刻调用</u>。

代码调用 Promise 对象内置的 then 方法，我们向这个方法中传入两个回调函数：一个成功回调函数和一个失败回调函数。当承诺成功兑现（在 promise 上调用 resolve）,前一个回调就会被调用，而当出现错误就会调用后一个回调函数（可以是发生了一个未处理的异常，也可以是在 promise 上调用了 reject）



简单回调函数的三个问题：

1. 错误难以处理
2. 执行连续步骤非常棘手
3. 执行很多并行任务也很棘手

## 深入研究 promise

promise对象用于作为 异步任务结果的占位符。它代表了 一个我们暂时还没获得但在未来有希望获得的值。

在一个 promise 对象的整个生命周期中，它会经历多种状态，如图 6.10 所示。一个 promise 对象从等待(pending)状态开始，此时我们对承诺的值一无所知。因此一个等待状态的 promise 对象也称为未实现(unresolved)的 promise。在程序执行的过程中，如果 promise 的 resolve 函数被调用，promise 就会进入完成(fulfilled)状态，在该状态下我们能够成功获取到承诺的值

![image-20181103093342369](http://markdown.icron.cc/promise-status.png)



如果 promise 的 reject 函数被调用，或者如果一个未处理的异常在 promise 调用的过程中发生了，promise 就会进入到拒绝状态，尽管在该状态下我们无法获取承诺的值，但我们至少知道了原因。一旦某个 promise 进入到完成态或者拒绝态，它的状态都不能再切换了(一个 promise 对象无法从完成态再进入拒绝态或者相反)。



```javascript
//promise的执行顺序
report('At code start');

var ninjaDelayedPromise = new Promise((resolve, reject) => {
  report('ninjaDelayedPromise executor');
  setTimeout(() => {
    report('Resolving ninjaDelayedPromise');
    resolve('Hattori');
  }, 500);
});

console.log(ninjaDelayedPromise);

assert(ninjaDelayedPromise !== null, 'After creating ninjaDelayedPromise');

ninjaDelayedPromise.then(ninja => {
  assert(
    ninja === 'Hattori',
    'ninjaDelayedPromise resolve handled with Hattori'
  );
});

const ninjaImmediatePromise = new Promise((resolve, reject) => {
  report('ninjaImmediatePromise executor.Immediate resolve.');
  resolve('Yoshi');
});

ninjaImmediatePromise.then(ninja => {
  assert(ninja === 'Yoshi', 'ninjaImmediatePromise resolve handled with Yoshi');
});

report('At code end');

//结果如下
At code start
ninjaDelayedPromise executor
Promise { <pending> }
After creating ninjaDelayedPromise
ninjaImmediatePromise executor.Immediate resolve.
At code end
ninjaImmediatePromise resolve handled with Yoshi
Resolving ninjaDelayedPromise
ninjaDelayedPromise resolve handled with Hattori
```

Promise 是设计用来处理异步任务的。JavaScript 通过本次事件循环中的所有代码都执行完毕后，调用 then 回调函数来处理 promise

## 拒绝promise

1. 显式拒绝：在一个 promise 的执行函数中调用传入的reject方法
2. 隐式拒绝：正处理一个 promise 的过程中抛出一个异常

```javascript
//一、显式拒绝
const promise = new Promise((resolve,reject) => {
    reject("Explicitly reject a promise");
})

//1.如果promise被拒绝,第二个回调函数error总是被调用
promise.then(
	() => fail("Happy path,won't be called!"),
    error => pass("A promise was explicitly rejected!")
)


//2.用catch处理拒绝
promise.then(
	() => fail("Happy path,won't be called!")
).catch(() => pass("Promise was also rejected"));
```

```javascript
//二、隐式拒绝
const promise = new Promise((resolve,reject) => {
    undeclaredVariable++;  //未定义 抛出错误
});

promise.then(()=>fail("Happy path,won't be called!"))
.catch(error => pass("Third promise was alse rejected"));
```



## 真实promise案例

```javascript
//从服务器获取数据
function getJSON(url){
    return new Promise((resolve,reject) => {
        const request = new XMLHttpRequest();
        
        request.open("GET",url);
        
        request.onload = function(){
            try{
                if(this.status === 200){
                    resolve(JSON.parse(this.response));  //无效的JSON代码
                }else{  //服务器返回错误
                    reject(this.status + " " + this.statusText);
                }
            }catch(e){
                reject(e.message);
            }
        }
        
        //通信中发生错误
        request.onerror = function(){
            reject(this.status + " " + this.statusText)
        }
        
        request.send();
    })
}

//3个潜在的错误源:客户端和服务器之间的连接错误、服务器返回错误的数据(无效的响应状态码)、无效的JSON代码
getJSON("data/ninjas.json").then(ninjas => {
    assert(ninjas !== null,"Ninjas obtained!");
}).catch(e => fail("Shouldn't be here:" + e));
```



## 链式调用 promise

我们可以在 then 函数上注册一个回调函数，一旦 promise 成功兑现就触发该回调函数

调用 then 方法后还可以再返回一个新的 promise 对象

```javascript
//链式调用 promise
getJSON('data/ninjas.json')
	.then(ninjas => getJSON(ninjas[0].missionsUrl))
	.then(missions => getJSON(missions[0].detailsUrl))
	.then(mission => assert(mission !== null,'Ninja mission obtained!'))
	.catch(error => fail('An error has occurred'))
```

### Promise 链中的错误捕获

```javascript
...catch(error => fail("An error has occurred:" + err));
```

如果错误在前边的任何一个 promise 中产生，catch 方法都会捕捉到，统一处理。



## 等待多个promise

```javascript
Promise.all([
    getJSON("data/ninjas.json"),
    getJSON("data/mapInfo.json"),
    getJSON("data/plan.json")
]).then(results => {
    const ninjas = results[0],mapInfo = results[1],plan = results[2];
   //...
}).catch(error => {
    fail("A problem in carrying out our plan!");
})
```

通过内置方法 `Promise.all` 可以等待多个 promise。这个方法将一个 promise 数组作为参数，然后创建一个新的 promise 对象，一旦数组中的 promise **全部被解决**，这个返回的 promise 就会被解决，一旦**其中有一个 promise 失败**了，那么整个新 promise 对象也会被拒绝。

后续的回调函数接收成功值组成的数组，数组中的每一项都对应 promise 数组中的对应项。

全部成功为成功，其中任意一个失败则失败 类似`&&`

## promise 竞赛

```javascript
Promise.race([
    getJSON("data/yoshi.json"),
    getJSON("data/hattori.json"),
    getJSON("data/hanzo.json")
]).then(ninja => {
    //...
}).catch(error => fail("Failure!"));
```

使用 Promise.race 方法传入一个 promise 数组会返回一个全新的 promise 对象，一旦数组中某一个 promise 被处理或被拒绝，这个返回的 promise 就同样会被处理或被拒绝。

任意一个成功或者失败 则整个状态为成功或失败





















---

原生 ajax

```javascript
var ajax = new XMLHttpRequest();  //1.创建
ajax.open('get','getStar.php');  //2.打开
ajax.send();  //3.发送
ajax.onreadystatechange = function(){  //4.接收
    if(ajax.readyState == 4 && ajax.status == 200){
        //数据返回了
        console.log(ajax.responseText);
    }
}
```























